Workbook
Name accountList: #REF!
Name beta_observed: #REF!
Name beta_unlev_comps: #REF!
Name check: #REF!
Name conversionfactor: '[10]E&P'!$D$6
Name convfactor: #REF!
Name costdebtfirm: #REF!
Name costequity: #REF!
Name days_per_year: #REF!
Name debt: #REF!
Name debt_weight: #REF!
Name market_equity: #REF!
Name relevered_beta: #REF!
Name risk_free_rate: #REF!
Name risk_premium: #REF!
Name stubyear: #REF!
Name totalcap: #REF!
Name wacc: #REF!

Sheet Proforma
E4: Projected Rate | H4: =Model2.0!I10 -> 1.0865743 | I4: =Model2.0!J10 -> 1.0938182 | J4: =Model2.0!K10 -> 1.1011103 | K4: =Model2.0!L10 -> 1.108451 | L4: =Model2.0!M10 -> 1.1158407 | M4: =Model2.0!N10 -> 1.1232796 | N4: =Model2.0!O10 -> 1.1307682 | O4: =Model2.0!P10 -> 1.1383066 | ... S4: =Model2.0!T10 -> 1.1689664
E5: General Vacancy | H5: =Model2.0!I11 -> 0.082781457 | I5: =Model2.0!J11 -> 0.082781457 | J5: =Model2.0!K11 -> 0.082781457 | K5: =Model2.0!L11 -> 0.082781457 | L5: =Model2.0!M11 -> 0.082781457 | M5: =Model2.0!N11 -> 0.082781457 | N5: =Model2.0!O11 -> 0.082781457 | O5: =Model2.0!P11 -> 0.082781457 | ... S5: =Model2.0!T11 -> 0.082781457
E8: Income | F8: T-12 Avg | G8: T-12 | H8: =Model2.0!I7 -> 46142 | I8: =Model2.0!J7 -> 46173 | J8: =Model2.0!K7 -> 46203 | K8: =Model2.0!L7 -> 46234 | L8: =Model2.0!M7 -> 46265 | M8: =Model2.0!N7 -> 46295 | N8: =Model2.0!O7 -> 46326 | O8: =Model2.0!P7 -> 46356 | ... S8: =Model2.0!T7 -> 46477 | U8: Current Mgmt | V8: IMPACT TO N.O.I
E9: Rental Income | F9: =G9/12 -> 69400.819 | G9: =Model2.0!F19 -> 832809.83 | H9: =Model2.0!I19 -> 89048.545 | I9: =Model2.0!J19 -> 89642.202 | J9: =Model2.0!K19 -> 90239.817 | K9: =Model2.0!L19 -> 90841.416 | L9: =Model2.0!M19 -> 91447.025 | M9: =Model2.0!N19 -> 92056.672 | N9: =Model2.0!O19 -> 92670.383 | O9: =Model2.0!P19 -> 93288.186 | ... S9: =Model2.0!T19 -> 95800.858 | T9: =Model2.0!BR19 -> 1108647.8 | U9: =Model2.0!BS19 -> 1133367.2 | V9: =Model2.0!BT19 -> -24719.431 | X9: =SUM(H9:S9) -> 1108647.8 | Y9: =X9-U9 -> -24719.431 | Z9: =IF(Y9=V9,"OK","Check") -> OK
E10: STORE Rate Mgmt. Rev | F10: =G10/12 -> 0 | G10: =Model2.0!F20 -> 0 | H10: =Model2.0!I20 -> 0 | I10: =Model2.0!J20 -> 0 | J10: =Model2.0!K20 -> 0 | K10: =Model2.0!L20 -> 4542.0708 | L10: =Model2.0!M20 -> 9114.4221 | M10: =Model2.0!N20 -> 13717.256 | N10: =Model2.0!O20 -> 15570.663 | O10: =Model2.0!P20 -> 17436.427 | ... S10: =Model2.0!T20 -> 25024.698 | T10: =Model2.0!BR20 -> 149034.2 | U10: =Model2.0!BS20 -> 0 | V10: =Model2.0!BT20 -> 149034.2 | X10: =SUM(H10:S10) -> 149034.2 | Y10: =X10-U10 -> 149034.2 | Z10: =IF(Y10=V10,"OK","Check") -> OK
E11: Discounts | F11: =G11/12 -> 0 | G11: =Model2.0!F21 -> 0 | H11: =Model2.0!I21 -> -3214.7489 | I11: =Model2.0!J21 -> -3236.1806 | J11: =Model2.0!K21 -> -3257.7551 | K11: =Model2.0!L21 -> -3279.4735 | L11: =Model2.0!M21 -> -3301.3367 | M11: =Model2.0!N21 -> -3323.3456 | N11: =Model2.0!O21 -> -3345.5012 | O11: =Model2.0!P21 -> -3367.8045 | ... S11: =Model2.0!T21 -> -3458.5147 | T11: =Model2.0!BR21 -> -40023.386 | U11: =Model2.0!BS21 -> -40023.386 | V11: =Model2.0!BT21 -> 0 | X11: =SUM(H11:S11) -> -40023.386 | Y11: =X11-U11 -> 0 | Z11: =IF(Y11=V11,"OK","Check") -> OK
E12: Net Rental Income | F12: =G12/12 -> 69400.819 | G12: =Model2.0!F22 -> 832809.83 | H12: =Model2.0!I22 -> 85833.797 | I12: =Model2.0!J22 -> 86406.022 | J12: =Model2.0!K22 -> 86982.062 | K12: =Model2.0!L22 -> 92104.013 | L12: =Model2.0!M22 -> 97260.111 | M12: =Model2.0!N22 -> 102450.58 | N12: =Model2.0!O22 -> 104895.55 | O12: =Model2.0!P22 -> 107356.81 | ... S12: =Model2.0!T22 -> 117367.04 | T12: =Model2.0!BR22 -> 1217658.6 | U12: =Model2.0!BS22 -> 1093343.8 | V12: =Model2.0!BT22 -> 124314.77 | X12: =SUM(H12:S12) -> 1217658.6 | Y12: =SUM(Y9:Y11) -> 124314.77 | Z12: =IF(ABS(Y12-V12)<1,"OK","Check") -> OK
C14: * | E14: Admin Fee Income | F14: =G14/12 -> 1847.0938 | G14: =Model2.0!F27 -> 22165.125 | H14: =Model2.0!I27 -> 580 | I14: =Model2.0!J27 -> 580 | J14: =Model2.0!K27 -> 580 | K14: =Model2.0!L27 -> 580 | L14: =Model2.0!M27 -> 580 | M14: =Model2.0!N27 -> 580 | N14: =Model2.0!O27 -> 580 | O14: =Model2.0!P27 -> 580 | ... S14: =Model2.0!T27 -> 580 | T14: =Model2.0!BR27 -> 6960 | U14: =Model2.0!BS27 -> 6960 | V14: =Model2.0!BT27 -> 0 | X14: =SUM(H14:S14) -> 6960 | Y14: =X14-U14 -> 0 | Z14: =IF(Y14=V14,"OK","Check") -> OK
C15: * | E15: Late Fee Income | F15: =G15/12 -> 1847.0938 | G15: =Model2.0!F28 -> 22165.125 | H15: =Model2.0!I28 -> 2392.1446 | I15: =Model2.0!J28 -> 2344.3017 | J15: =Model2.0!K28 -> 2297.4157 | K15: =Model2.0!L28 -> 2251.4674 | L15: =Model2.0!M28 -> 2206.438 | M15: =Model2.0!N28 -> 2162.3092 | N15: =Model2.0!O28 -> 2119.0631 | O15: =Model2.0!P28 -> 2076.6818 | ... S15: =Model2.0!T28 -> 1915.4652 | T15: =Model2.0!BR28 -> 25749.436 | U15: =Model2.0!BS28 -> 25749.436 | V15: =Model2.0!BT28 -> 0 | X15: =SUM(H15:S15) -> 25749.436 | Y15: =X15-U15 -> 0 | Z15: =IF(Y15=V15,"OK","Check") -> OK
E16: Current Tenant Protection Split | F16: =G16/12 -> 2983 | G16: =Model2.0!F29 -> 35796 | H16: =Model2.0!I29 -> 2988.966 | I16: =Model2.0!J29 -> 2994.9439 | J16: =Model2.0!K29 -> 3000.9338 | K16: =Model2.0!L29 -> 3006.9357 | L16: =Model2.0!M29 -> 3012.9496 | M16: =Model2.0!N29 -> 3018.9755 | N16: =Model2.0!O29 -> 3025.0134 | O16: =Model2.0!P29 -> 3031.0634 | ... S16: =Model2.0!T29 -> 3055.3848 | T16: =Model2.0!BR29 -> 0 | U16: =Model2.0!BS29 -> 36264.778 | V16: =Model2.0!BT29 -> 0 | X16: =SUM(H16:S16) -> 36264.778 | Y16: =X16-U16 -> 0 | Z16: =IF(Y16=V16,"OK","Check") -> OK | AG16: =T47 -> 1001731.7 | AH16: 634336.54 | AI16: 802467.17
E17: STORE Tenant Protection Split | F17: =G17/12 -> 0 | G17: =Model2.0!F30 -> 0 | H17: =Model2.0!I30 -> 2747.84 | I17: =Model2.0!J30 -> 2836.48 | J17: =Model2.0!K30 -> 2925.12 | K17: =Model2.0!L30 -> 3013.76 | L17: =Model2.0!M30 -> 3102.4 | M17: =Model2.0!N30 -> 3191.04 | N17: =Model2.0!O30 -> 3279.68 | O17: =Model2.0!P30 -> 3368.32 | ... S17: =Model2.0!T30 -> 3545.6 | T17: =Model2.0!BR30 -> 38558.4 | U17: =Model2.0!BS30 -> 0 | V17: =Model2.0!BT30 -> 2293.6223 | X17: =SUM(H17:S17) -> 38558.4 | Y17: =X17-U17 -> 38558.4 | Z17: =IF(Y17=V17,"OK","Check") -> Check | AF17: 0.05 | AG17: =$AG$16/$AF17 -> 20034633 | AH17: =AH$16/$AF17 -> 12686731 | AI17: =AI$16/$AF17 -> 16049343 | AK17: =AG17-AI17 -> 3985289.9
E18: Other Tenant Income | F18: =G18/12 -> 0 | G18: =Model2.0!F31 -> 0 | H18: =Model2.0!I31 -> 0 | I18: =Model2.0!J31 -> 0 | J18: =Model2.0!K31 -> 0 | K18: =Model2.0!L31 -> 0 | L18: =Model2.0!M31 -> 0 | M18: =Model2.0!N31 -> 0 | N18: =Model2.0!O31 -> 0 | O18: =Model2.0!P31 -> 0 | ... S18: =Model2.0!T31 -> 0 | T18: =Model2.0!BR31 -> 0 | U18: =Model2.0!BS31 -> 0 | V18: =Model2.0!BT31 -> 0 | X18: =SUM(H18:S18) -> 0 | Y18: =X18-U18 -> 0 | Z18: =IF(Y18=V18,"OK","Check") -> OK | AF18: 0.055 | AG18: =$AG$16/$AF18 -> 18213303 | AH18: =AH$16/$AF18 -> 11533392 | AI18: =AI$16/$AF18 -> 14590312 | AK18: =AG18-AI18 -> 3622990.8
E19: Retail Sales Income | F19: =G19/12 -> 852.66083 | G19: =Model2.0!F32 -> 10231.93 | H19: =Model2.0!I32 -> 849.04136 | I19: =Model2.0!J32 -> 850.73944 | J19: =Model2.0!K32 -> 852.44092 | K19: =Model2.0!L32 -> 854.1458 | L19: =Model2.0!M32 -> 855.8541 | M19: =Model2.0!N32 -> 857.5658 | N19: =Model2.0!O32 -> 859.28093 | O19: =Model2.0!P32 -> 860.9995 | ... S19: =Model2.0!T32 -> 867.90818 | T19: =Model2.0!BR32 -> 10301.32 | U19: =Model2.0!BS32 -> 10301.32 | V19: =Model2.0!BT32 -> 0 | X19: =SUM(H19:S19) -> 10301.32 | Y19: =X19-U19 -> 0 | Z19: =IF(Y19=V19,"OK","Check") -> OK | AF19: 0.06 | AG19: =$AG$16/$AF19 -> 16695528 | AH19: =AH$16/$AF19 -> 10572276 | AI19: =AI$16/$AF19 -> 13374453 | AK19: =AG19-AI19 -> 3321074.9
AF20: 0.065 | AG20: =$AG$16/$AF20 -> 15411256 | AH20: =AH$16/$AF20 -> 9759023.7 | AI20: =AI$16/$AF20 -> 12345649 | AK20: =AG20-AI20 -> 3065607.6
E21: Total Operating Income | F21: =G21/12 -> 76930.667 | G21: =Model2.0!F34 -> 923168.01 | H21: =Model2.0!I34 -> 92402.822 | I21: =Model2.0!J34 -> 93017.543 | J21: =Model2.0!K34 -> 93637.039 | K21: =Model2.0!L34 -> 98803.386 | L21: =Model2.0!M34 -> 104004.8 | M21: =Model2.0!N34 -> 109241.5 | N21: =Model2.0!O34 -> 111733.57 | O21: =Model2.0!P34 -> 114242.81 | ... S21: =Model2.0!T34 -> 124276.02 | T21: =Model2.0!BR34 -> 1299227.8 | U21: =Model2.0!BS34 -> 1172619.4 | V21: =Model2.0!BT34 -> 126608.39 | X21: =SUM(H21:S21) -> 1299227.8 | Y21: =SUM(Y12:Y19) -> 162873.17 | Z21: =IF(Y21=V21,"OK","Check") -> Check
E23: Expenses
E24: Advertising & Marketing | F24: =G24/12 -> 2904.785 | G24: =Model2.0!F37 -> 34857.42 | H24: =Model2.0!I37 -> 3000 | I24: =Model2.0!J37 -> 3000 | J24: =Model2.0!K37 -> 3000 | K24: =Model2.0!L37 -> 3000 | L24: =Model2.0!M37 -> 3000 | M24: =Model2.0!N37 -> 3000 | N24: =Model2.0!O37 -> 3000 | O24: =Model2.0!P37 -> 3000 | ... S24: =Model2.0!T37 -> 3000 | T24: =Model2.0!BR37 -> 36000 | U24: =Model2.0!BS37 -> 36000 | V24: =Model2.0!BT37 -> 0 | X24: =SUM(H24:S24) -> 36000 | Y24: =U24-X24 -> 0 | Z24: =IF(Y24=V24,"OK","Check") -> OK
E25: Current Payment Processing Fees | F25: =G25/12 -> 1111.145 | G25: =Model2.0!F38 -> 13333.74 | H25: =Model2.0!I38 -> 1333.3464 | I25: =Model2.0!J38 -> 1342.2167 | J25: =Model2.0!K38 -> 1351.1558 | K25: =Model2.0!L38 -> 1425.7048 | L25: =Model2.0!M38 -> 1500.7597 | M25: =Model2.0!N38 -> 1576.3237 | N25: =Model2.0!O38 -> 1612.2836 | O25: =Model2.0!P38 -> 1648.4912 | ... S25: =Model2.0!T38 -> 1793.2675 | T25: =Model2.0!BR38 -> 0 | U25: =Model2.0!BS38 -> 18747.487 | V25: =Model2.0!BT38 -> 0 | X25: =SUM(H25:S25) -> 18747.487 | Y25: =U25-X25 -> 0 | Z25: =IF(Y25=V25,"OK","Check") -> OK
E26: STORE Payment Processing Fees | F26: =G26/12 -> 0 | G26: =Model2.0!F39 -> 0 | H26: =Model2.0!I39 -> 0 | I26: =Model2.0!J39 -> 0 | J26: =Model2.0!K39 -> 0 | K26: =Model2.0!L39 -> 0 | L26: =Model2.0!M39 -> 0 | M26: =Model2.0!N39 -> 0 | N26: =Model2.0!O39 -> 0 | O26: =Model2.0!P39 -> 0 | ... S26: =Model2.0!T39 -> 0 | T26: =Model2.0!BR39 -> 0 | U26: =Model2.0!BS39 -> 0 | V26: =Model2.0!BT39 -> 18747.487 | X26: =SUM(H26:S26) -> 0 | Y26: =X25-X26 -> 18747.487 | Z26: =IF(Y26=V26,"OK","Check") -> OK
E27: Fire Prevention | F27: =G27/12 -> 0 | G27: =Model2.0!F40 -> 0 | H27: =Model2.0!I40 -> 632.95194 | I27: =Model2.0!J40 -> 632.95194 | J27: =Model2.0!K40 -> 632.95194 | K27: =Model2.0!L40 -> 632.95194 | L27: =Model2.0!M40 -> 632.95194 | M27: =Model2.0!N40 -> 632.95194 | N27: =Model2.0!O40 -> 632.95194 | O27: =Model2.0!P40 -> 632.95194 | ... S27: =Model2.0!T40 -> 632.95194 | T27: =Model2.0!BR40 -> 7595.4233 | U27: =Model2.0!BS40 -> 7595.4233 | V27: =Model2.0!BT40 -> 0 | X27: =SUM(H27:S27) -> 7595.4233 | Y27: =U27-X27 -> 0 | Z27: =IF(Y27=V27,"OK","Check") -> OK
E28: Licenses & Permits | F28: =G28/12 -> 34.1875 | G28: =Model2.0!F41 -> 410.25 | H28: =Model2.0!I41 -> 34.1875 | I28: =Model2.0!J41 -> 34.1875 | J28: =Model2.0!K41 -> 34.1875 | K28: =Model2.0!L41 -> 34.1875 | L28: =Model2.0!M41 -> 34.1875 | M28: =Model2.0!N41 -> 34.1875 | N28: =Model2.0!O41 -> 34.1875 | O28: =Model2.0!P41 -> 34.1875 | ... S28: =Model2.0!T41 -> 34.1875 | T28: =Model2.0!BR41 -> 410.25 | U28: =Model2.0!BS41 -> 410.25 | V28: =Model2.0!BT41 -> 0 | X28: =SUM(H28:S28) -> 410.25 | Y28: =U28-X28 -> 0 | Z28: =IF(Y28=V28,"OK","Check") -> OK
E29: Current Mgmt. Fee | F29: =G29/12 -> 3910.3633 | G29: =Model2.0!F42 -> 46924.36 | H29: =Model2.0!I42 -> 5150.0278 | I29: =Model2.0!J42 -> 5184.3613 | J29: =Model2.0!K42 -> 5218.9237 | K29: =Model2.0!L42 -> 5526.2408 | L29: =Model2.0!M42 -> 5835.6066 | M29: =Model2.0!N42 -> 6147.0349 | N29: =Model2.0!O42 -> 6293.7327 | O29: =Model2.0!P42 -> 6441.4085 | ... S29: =Model2.0!T42 -> 7042.0225 | T29: =Model2.0!BR42 -> 0 | U29: =Model2.0!BS42 -> 73059.517 | V29: =Model2.0!BT42 -> 0 | X29: =SUM(H29:S29) -> 73059.517 | Y29: =U29-X29 -> 0 | Z29: =IF(Y29=V29,"OK","Check") -> OK
E30: STORE Mgmt. Fee | F30: =G30/12 -> 0 | G30: =Model2.0!F43 -> 0 | H30: =Model2.0!I43 -> 3433.3519 | I30: =Model2.0!J43 -> 3456.2409 | J30: =Model2.0!K43 -> 3479.2825 | K30: =Model2.0!L43 -> 3684.1605 | L30: =Model2.0!M43 -> 3890.4044 | M30: =Model2.0!N43 -> 4098.0233 | N30: =Model2.0!O43 -> 4195.8218 | O30: =Model2.0!P43 -> 4294.2723 | ... S30: =Model2.0!T43 -> 4694.6817 | T30: =Model2.0!BR43 -> 48706.345 | U30: =Model2.0!BS43 -> 0 | V30: =Model2.0!BT43 -> 24353.172 | X30: =SUM(H30:S30) -> 48706.345 | Y30: =X29-X30 -> 24353.172 | Z30: =IF(Y30=V30,"OK","Check") -> OK
E31: Payroll | F31: =G31/12 -> 7490.3592 | G31: =Model2.0!F44 -> 89884.31 | H31: =Model2.0!I44 -> 7918.572 | I31: =Model2.0!J44 -> 7918.572 | J31: =Model2.0!K44 -> 7918.572 | K31: =Model2.0!L44 -> 7918.572 | L31: =Model2.0!M44 -> 7918.572 | M31: =Model2.0!N44 -> 7918.572 | N31: =Model2.0!O44 -> 7918.572 | O31: =Model2.0!P44 -> 7918.572 | ... S31: =Model2.0!T44 -> 7918.572 | T31: =Model2.0!BR44 -> 95022.864 | U31: =Model2.0!BS44 -> 91681.996 | V31: =Model2.0!BT44 -> -3340.8674 | X31: =SUM(H31:S31) -> 95022.864 | Y31: =U31-X31 -> -3340.8674 | Z31: =IF(Y31=V31,"OK","Check") -> OK
E32: Office Supplies | F32: =G32/12 -> 138.32667 | G32: =Model2.0!F45 -> 1659.92 | H32: =Model2.0!I45 -> 138.32667 | I32: =Model2.0!J45 -> 138.32667 | J32: =Model2.0!K45 -> 138.32667 | K32: =Model2.0!L45 -> 138.32667 | L32: =Model2.0!M45 -> 138.32667 | M32: =Model2.0!N45 -> 138.32667 | N32: =Model2.0!O45 -> 138.32667 | O32: =Model2.0!P45 -> 138.32667 | ... S32: =Model2.0!T45 -> 138.32667 | T32: =Model2.0!BR45 -> 1659.92 | U32: =Model2.0!BS45 -> 1659.92 | V32: =Model2.0!BT45 -> 0 | X32: =SUM(H32:S32) -> 1659.92 | Y32: =U32-X32 -> 0 | Z32: =IF(Y32=V32,"OK","Check") -> OK
E33: Repairs & Maintenance | F33: =G33/12 -> 3315.6358 | G33: =Model2.0!F46 -> 39787.63 | H33: =Model2.0!I46 -> 3315.6358 | I33: =Model2.0!J46 -> 3315.6358 | J33: =Model2.0!K46 -> 3315.6358 | K33: =Model2.0!L46 -> 3315.6358 | L33: =Model2.0!M46 -> 3315.6358 | M33: =Model2.0!N46 -> 3315.6358 | N33: =Model2.0!O46 -> 3315.6358 | O33: =Model2.0!P46 -> 3315.6358 | ... S33: =Model2.0!T46 -> 3315.6358 | T33: =Model2.0!BR46 -> 39787.63 | U33: =Model2.0!BS46 -> 39787.63 | V33: =Model2.0!BT46 -> 0 | X33: =SUM(H33:S33) -> 39787.63 | Y33: =U33-X33 -> 0 | Z33: =IF(Y33=V33,"OK","Check") -> OK
E34: Security | F34: =G34/12 -> 0 | G34: =Model2.0!F47 -> 0 | H34: =Model2.0!I47 -> 120 | I34: =Model2.0!J47 -> 120 | J34: =Model2.0!K47 -> 120 | K34: =Model2.0!L47 -> 120 | L34: =Model2.0!M47 -> 120 | M34: =Model2.0!N47 -> 120 | N34: =Model2.0!O47 -> 120 | O34: =Model2.0!P47 -> 120 | ... S34: =Model2.0!T47 -> 120 | T34: =Model2.0!BR47 -> 1440 | U34: =Model2.0!BS47 -> 0 | V34: =Model2.0!BT47 -> -1440 | X34: =SUM(H34:S34) -> 1440 | Y34: =U34-X34 -> -1440 | Z34: =IF(Y34=V34,"OK","Check") -> OK
E35: Retail Products | F35: =G35/12 -> 308.0475 | G35: =Model2.0!F48 -> 3696.57 | H35: =Model2.0!I48 -> 308.0475 | I35: =Model2.0!J48 -> 308.0475 | J35: =Model2.0!K48 -> 308.0475 | K35: =Model2.0!L48 -> 308.0475 | L35: =Model2.0!M48 -> 308.0475 | M35: =Model2.0!N48 -> 308.0475 | N35: =Model2.0!O48 -> 308.0475 | O35: =Model2.0!P48 -> 308.0475 | ... S35: =Model2.0!T48 -> 308.0475 | T35: =Model2.0!BR48 -> 3696.57 | U35: =Model2.0!BS48 -> 3696.57 | V35: =Model2.0!BT48 -> 0 | X35: =SUM(H35:S35) -> 3696.57 | Y35: =U35-X35 -> 0 | Z35: =IF(Y35=V35,"OK","Check") -> OK
E36: Telephone & Internet | F36: =G36/12 -> 909.45917 | G36: =Model2.0!F49 -> 10913.51 | H36: =Model2.0!I49 -> 909.45917 | I36: =Model2.0!J49 -> 909.45917 | J36: =Model2.0!K49 -> 909.45917 | K36: =Model2.0!L49 -> 909.45917 | L36: =Model2.0!M49 -> 909.45917 | M36: =Model2.0!N49 -> 909.45917 | N36: =Model2.0!O49 -> 909.45917 | O36: =Model2.0!P49 -> 909.45917 | ... S36: =Model2.0!T49 -> 909.45917 | T36: =Model2.0!BR49 -> 10913.51 | U36: =Model2.0!BS49 -> 10913.51 | V36: =Model2.0!BT49 -> 0 | X36: =SUM(H36:S36) -> 10913.51 | Y36: =U36-X36 -> 0 | Z36: =IF(Y36=V36,"OK","Check") -> OK
E37: Software | F37: =G37/12 -> 1441.68 | G37: =Model2.0!F50 -> 17300.16 | H37: =Model2.0!I50 -> 1850 | I37: =Model2.0!J50 -> 1850 | J37: =Model2.0!K50 -> 1850 | K37: =Model2.0!L50 -> 1850 | L37: =Model2.0!M50 -> 1850 | M37: =Model2.0!N50 -> 1850 | N37: =Model2.0!O50 -> 1850 | O37: =Model2.0!P50 -> 1850 | ... S37: =Model2.0!T50 -> 1850 | T37: =Model2.0!BR50 -> 22200 | U37: =Model2.0!BS50 -> 17296.04 | V37: =Model2.0!BT50 -> -4903.96 | X37: =SUM(H37:S37) -> 22200 | Y37: =U37-X37 -> -4903.96 | Z37: =IF(Y37=V37,"OK","Check") -> OK
E38: Bank Charges | F38: =G38/12 -> 0 | G38: =Model2.0!F51 -> 0 | H38: =Model2.0!I51 -> 0 | I38: =Model2.0!J51 -> 0 | J38: =Model2.0!K51 -> 0 | K38: =Model2.0!L51 -> 0 | L38: =Model2.0!M51 -> 0 | M38: =Model2.0!N51 -> 0 | N38: =Model2.0!O51 -> 0 | O38: =Model2.0!P51 -> 0 | ... S38: =Model2.0!T51 -> 0 | T38: =Model2.0!BR51 -> 0 | U38: =Model2.0!BS51 -> 0 | V38: =Model2.0!BT51 -> 0
E39: Prof Fees - Legal/Acctg | F39: =G39/12 -> 161.73 | G39: =Model2.0!F52 -> 1940.76 | H39: =Model2.0!I52 -> 161.73 | I39: =Model2.0!J52 -> 161.73 | J39: =Model2.0!K52 -> 161.73 | K39: =Model2.0!L52 -> 161.73 | L39: =Model2.0!M52 -> 161.73 | M39: =Model2.0!N52 -> 161.73 | N39: =Model2.0!O52 -> 161.73 | O39: =Model2.0!P52 -> 161.73 | ... S39: =Model2.0!T52 -> 161.73 | T39: =Model2.0!BR52 -> 1940.76 | U39: =Model2.0!BS52 -> 1940.76 | V39: =Model2.0!BT52 -> 0 | X39: =SUM(H39:S39) -> 1940.76 | Y39: =U39-X39 -> 0 | Z39: =IF(Y39=V39,"OK","Check") -> OK
E40: Utilities | F40: =G40/12 -> 2343.57 | G40: =Model2.0!F53 -> 28122.84 | H40: =Model2.0!I53 -> 2343.57 | I40: =Model2.0!J53 -> 2343.57 | J40: =Model2.0!K53 -> 2343.57 | K40: =Model2.0!L53 -> 2343.57 | L40: =Model2.0!M53 -> 2343.57 | M40: =Model2.0!N53 -> 2343.57 | N40: =Model2.0!O53 -> 2343.57 | O40: =Model2.0!P53 -> 2343.57 | ... S40: =Model2.0!T53 -> 2343.57 | T40: =Model2.0!BR53 -> 28122.84 | U40: =Model2.0!BS53 -> 28122.84 | V40: =Model2.0!BT53 -> 0 | X40: =SUM(H40:S40) -> 28122.84 | Y40: =U40-X40 -> 0 | Z40: =IF(Y40=V40,"OK","Check") -> OK
E41: Insurance | F41: =G41/12 -> 0 | G41: =Model2.0!F54 -> 0 | H41: =Model2.0!I54 -> 0 | I41: =Model2.0!J54 -> 0 | J41: =Model2.0!K54 -> 0 | K41: =Model2.0!L54 -> 0 | L41: =Model2.0!M54 -> 0 | M41: =Model2.0!N54 -> 0 | N41: =Model2.0!O54 -> 0 | O41: =Model2.0!P54 -> 0 | ... S41: =Model2.0!T54 -> 0 | T41: =Model2.0!BR54 -> 0 | U41: =Model2.0!BS54 -> 0 | V41: =Model2.0!BT54 -> 0 | X41: =SUM(H41:S41) -> 0 | Y41: =U41-X41 -> 0 | Z41: =IF(Y41=V41,"OK","Check") -> OK
E42: Property Taxes | F42: =G42/12 -> 0 | G42: =Model2.0!F55 -> 0 | H42: =Model2.0!I55 -> 0 | I42: =Model2.0!J55 -> 0 | J42: =Model2.0!K55 -> 0 | K42: =Model2.0!L55 -> 0 | L42: =Model2.0!M55 -> 0 | M42: =Model2.0!N55 -> 0 | N42: =Model2.0!O55 -> 0 | O42: =Model2.0!P55 -> 0 | ... S42: =Model2.0!T55 -> 0 | T42: =Model2.0!BR55 -> 0 | U42: =Model2.0!BS55 -> 0 | V42: =Model2.0!BT55 -> 0 | X42: =SUM(H42:S42) -> 0 | Y42: =U42-X42 -> 0 | Z42: =IF(Y42=V42,"OK","Check") -> OK
E43: Other Expense | F43: =G43/12 -> 0 | G43: =Model2.0!F56 -> 0 | H43: =Model2.0!I56 -> 0 | I43: =Model2.0!J56 -> 0 | J43: =Model2.0!K56 -> 0 | K43: =Model2.0!L56 -> 0 | L43: =Model2.0!M56 -> 0 | M43: =Model2.0!N56 -> 0 | N43: =Model2.0!O56 -> 0 | O43: =Model2.0!P56 -> 0 | ... S43: =Model2.0!T56 -> 0 | T43: =Model2.0!BR56 -> 0 | U43: =Model2.0!BS56 -> 0 | V43: =Model2.0!BT56 -> 0
E45: Total Operating Expense | F45: =G45/12 -> 24069.289 | G45: =Model2.0!F58 -> 288831.47 | H45: =Model2.0!I58 -> 24165.832 | I45: =Model2.0!J58 -> 24188.721 | J45: =Model2.0!K58 -> 24211.763 | K45: =Model2.0!L58 -> 24416.641 | L45: =Model2.0!M58 -> 24622.885 | M45: =Model2.0!N58 -> 24830.504 | N45: =Model2.0!O58 -> 24928.302 | O45: =Model2.0!P58 -> 25026.753 | ... S45: =Model2.0!T58 -> 25427.162 | T45: =Model2.0!BR58 -> 297496.11 | U45: =Model2.0!BS58 -> 330911.94 | V45: =Model2.0!BT58 -> 33415.832 | W45: =V45/U45 -> 0.10098104 | X45: =SUM(H45:S45) -> 297496.11 | Y45: =SUM(Y24:Y42) -> 33415.832 | Z45: =IF(Y45=V45,"OK","Check") -> OK
E47: Net Operating Income | F47: =G47/12 -> 52861.378 | G47: =Model2.0!F60 -> 634336.54 | H47: =Model2.0!I60 -> 68236.99 | I47: =Model2.0!J60 -> 68828.822 | J47: =Model2.0!K60 -> 69425.276 | K47: =Model2.0!L60 -> 74386.745 | L47: =Model2.0!M60 -> 79381.918 | M47: =Model2.0!N60 -> 84410.993 | N47: =Model2.0!O60 -> 86805.267 | O47: =Model2.0!P60 -> 89216.057 | ... S47: =Model2.0!T60 -> 98848.853 | T47: =Model2.0!BR60 -> 1001731.7 | U47: =Model2.0!BS60 -> 841707.44 | V47: =Model2.0!BT60 -> 160024.22 | W47: =V47/U47 -> 0.19011858
H49: =H21-H45 -> 68236.99 | I49: =I21-I45 -> 68828.822 | J49: =J21-J45 -> 69425.276 | K49: =K21-K45 -> 74386.745 | L49: =L21-L45 -> 79381.918 | M49: =M21-M45 -> 84410.993 | N49: =N21-N45 -> 86805.267 | O49: =O21-O45 -> 89216.057 | ... S49: =S21-S45 -> 98848.853
H50: =IF(H49=H47,"OK","Check") -> OK | I50: =IF(I49=I47,"OK","Check") -> OK | J50: =IF(J49=J47,"OK","Check") -> OK | K50: =IF(K49=K47,"OK","Check") -> OK | L50: =IF(L49=L47,"OK","Check") -> OK | M50: =IF(M49=M47,"OK","Check") -> OK | N50: =IF(N49=N47,"OK","Check") -> OK | O50: =IF(O49=O47,"OK","Check") -> OK | ... S50: =IF(S49=S47,"OK","Check") -> OK

Sheet 5 Year Proforma
D2: Wentworth - Vacaville, CA
D3: 5-Year Proforma
G6: 1 | L6: 2 | Q6: 3 | V6: 4 | AA6: 5
G7: 2027 | H7: Assumptions | L7: 2028 | M7: Assumptions | Q7: 2029 | R7: Assumptions | V7: 2030 | W7: Assumptions | AA7: 2031 | AB7: Assumptions
D8: Income
D9: Rental Income | G9: =Model2.0!BW19 -> 1108647.8 | L9: =Model2.0!BX19 -> 1174825.5 | M9: =(L9-G9)/G9 -> 0.059692273 | Q9: =Model2.0!BY19 -> 1222689.7 | R9: =(Q9-L9)/L9 -> 0.040741543 | V9: =Model2.0!BZ19 -> 1272504 | W9: =(V9-Q9)/Q9 -> 0.040741543 | AA9: =Model2.0!CA19 -> 1324347.8 | AB9: =(AA9-V9)/V9 -> 0.040741543
D10: STORE Rate Mgmt. Rev. | G10: =Model2.0!BW20 -> 149034.2 | H10: =IF(G10>0,G10/G9,"") -> 0.13442881 | L10: =Model2.0!BX20 -> 122035.47 | M10: =IF(L10>0,L10/L9,"") -> 0.1038754 | Q10: =Model2.0!BY20 -> 127007.39 | R10: =IF(Q10>0,Q10/Q9,"") -> 0.1038754 | V10: =Model2.0!BZ20 -> 132181.86 | W10: =IF(V10>0,V10/V9,"") -> 0.1038754 | AA10: =Model2.0!CA20 -> 137567.16 | AB10: =IF(AA10>0,AA10/AA9,"") -> 0.1038754
D11: Discounts | G11: =Model2.0!BW21 -> -40023.386 | L11: =Model2.0!BX21 -> -42412.473 | Q11: =Model2.0!BY21 -> -44140.423 | R11: =(Q11-L11)/L11 -> 0.040741543 | V11: =Model2.0!BZ21 -> -45938.772 | W11: =(V11-Q11)/Q11 -> 0.040741543 | AA11: =Model2.0!CA21 -> -47810.388 | AB11: =(AA11-V11)/V11 -> 0.040741543 | AK11: we looked at your original proforma and it does look like there's a significant delay in revenue
D12: Net Rental Income | G12: =Model2.0!BW22 -> 1217658.6 | L12: =Model2.0!BX22 -> 1254448.5 | Q12: =Model2.0!BY22 -> 1305556.7 | V12: =Model2.0!BZ22 -> 1358747.1 | AA12: =Model2.0!CA22 -> 1414104.5
D14: Admin Fee Income | G14: =Model2.0!BW27 -> 6960 | L14: =Model2.0!BX27 -> 6960 | Q14: =Model2.0!BY27 -> 6960 | V14: =Model2.0!BZ27 -> 6960 | AA14: =Model2.0!CA27 -> 6960
D15: Late Fee Income | G15: =Model2.0!BW28 -> 25749.436 | L15: =Model2.0!BX28 -> 20206.013 | Q15: =Model2.0!BY28 -> 15855.997 | V15: =Model2.0!BZ28 -> 12442.466 | W15: 4% Ann. Growth | AA15: =Model2.0!CA28 -> 9763.8109 | AB15: 4% Ann. Growth
D16: Current Tenant Protection Split | G16: =Model2.0!BW29 -> 36264.778 | L16: =Model2.0!BX29 -> 37144.77 | Q16: =Model2.0!BY29 -> 38046.117 | V16: =Model2.0!BZ29 -> 38969.335 | AA16: =Model2.0!CA29 -> 39914.956
D17: STORE Tenant Protection Split | G17: =Model2.0!BW30 -> 38558.4 | L17: =Model2.0!BX30 -> 43185.408 | Q17: =Model2.0!BY30 -> 43833.189 | V17: =Model2.0!BZ30 -> 44490.687 | AA17: =Model2.0!CA30 -> 45158.047 | AG17: x | AH17: increase
D18: Other Tenant Income | G18: =Model2.0!BW31 -> 0 | L18: =Model2.0!BX31 -> 0 | Q18: =Model2.0!BY31 -> 0 | V18: =Model2.0!BZ31 -> 0 | AA18: =Model2.0!CA31 -> 0
D19: Retail Sales Income | G19: =Model2.0!BW32 -> 10301.32 | L19: =Model2.0!BX32 -> 10551.29 | Q19: =Model2.0!BY32 -> 10807.325 | V19: =Model2.0!BZ32 -> 11069.573 | AA19: =Model2.0!CA32 -> 11338.185
D21: Total Operating Income | G21: =SUM(G12:G15,G17:G19) -> 1299227.8 | L21: =SUM(L12:L15,L17:L19) -> 1335351.2 | Q21: =SUM(Q12:Q15,Q17:Q19) -> 1383013.2 | V21: =SUM(V12:V15,V17:V19) -> 1433709.8 | AA21: =SUM(AA12:AA15,AA17:AA19) -> 1487324.6
D23: Expenses
D24: Advertising & Marketing | G24: =Model2.0!BW37 -> 36000 | L24: =Model2.0!BX37 -> 36720 | Q24: =Model2.0!BY37 -> 37454.4 | V24: =Model2.0!BZ37 -> 38203.488 | AA24: =Model2.0!CA37 -> 38967.558
D25: Current Payment Processing Fees | G25: =Model2.0!BW38 -> 18747.487 | L25: =Model2.0!BX38 -> 19268.738 | Q25: =Model2.0!BY38 -> 19956.487 | V25: =Model2.0!BZ38 -> 20688.024 | AA25: =Model2.0!CA38 -> 21461.67 | AG25: x | AH25: increase
D26: STORE Payment Processing Fees | G26: =Model2.0!BW39 -> 0 | L26: =Model2.0!BX39 -> 0 | Q26: =Model2.0!BY39 -> 0 | V26: =Model2.0!BZ39 -> 0 | AA26: =Model2.0!CA39 -> 0
D27: Fire Prevention | G27: =Model2.0!BW40 -> 7595.4233 | L27: =Model2.0!BX40 -> 7747.3318 | Q27: =Model2.0!BY40 -> 7902.2784 | V27: =Model2.0!BZ40 -> 8060.324 | AA27: =Model2.0!CA40 -> 8221.5305
D28: Licenses & Permits | G28: =Model2.0!BW41 -> 410.25 | L28: =Model2.0!BX41 -> 418.455 | Q28: =Model2.0!BY41 -> 426.8241 | V28: =Model2.0!BZ41 -> 435.36058 | AA28: =Model2.0!CA41 -> 444.06779
D29: Current Mgmt. Fee | G29: =Model2.0!BW42 -> 73059.517 | L29: =Model2.0!BX42 -> 75266.911 | Q29: =Model2.0!BY42 -> 78333.401 | V29: =Model2.0!BZ42 -> 81524.824 | AA29: =Model2.0!CA42 -> 84846.271
D30: STORE Mgmt. Fee | G30: =Model2.0!BW43 -> 48706.345 | L30: =Model2.0!BX43 -> 56450.183 | Q30: =Model2.0!BY43 -> 65277.834 | V30: =Model2.0!BZ43 -> 67937.354 | AA30: =Model2.0!CA43 -> 70705.226 | AG30: Increase Mgmt
D31: Payroll | G31: =Model2.0!BW44 -> 95022.864 | H31: ='Inputs & Drivers'!$E$54 -> 62Hrs/Wk @ $26 + Burden Rate | L31: =Model2.0!BX44 -> 96923.321 | M31: ='Inputs & Drivers'!$E$54 -> 62Hrs/Wk @ $26 + Burden Rate | Q31: =Model2.0!BY44 -> 98861.787 | R31: ='Inputs & Drivers'!$E$54 -> 62Hrs/Wk @ $26 + Burden Rate | V31: =Model2.0!BZ44 -> 100839.02 | W31: ='Inputs & Drivers'!$E$54 -> 62Hrs/Wk @ $26 + Burden Rate | AA31: =Model2.0!CA44 -> 102855.8 | AB31: ='Inputs & Drivers'!$E$54 -> 62Hrs/Wk @ $26 + Burden Rate
D32: Office Supplies | G32: =Model2.0!BW45 -> 1659.92 | L32: =Model2.0!BX45 -> 1693.1184 | Q32: =Model2.0!BY45 -> 1726.9808 | V32: =Model2.0!BZ45 -> 1761.5204 | AA32: =Model2.0!CA45 -> 1796.7508
D33: Repairs & Maintenance | G33: =Model2.0!BW46 -> 39787.63 | H33: Includes... & Preventive Maint. | L33: =Model2.0!BX46 -> 40583.383 | Q33: =Model2.0!BY46 -> 41395.05 | V33: =Model2.0!BZ46 -> 42222.951 | AA33: =Model2.0!CA46 -> 43067.41
D34: Security | G34: =Model2.0!BW47 -> 1440 | H34: Includes Gate Access & 24-Hour Monitoring | L34: =Model2.0!BX47 -> 1468.8 | Q34: =Model2.0!BY47 -> 1498.176 | V34: =Model2.0!BZ47 -> 1528.1395 | AA34: =Model2.0!CA47 -> 1558.7023
D35: Retail Products | G35: =Model2.0!BW48 -> 3696.57 | L35: =Model2.0!BX48 -> 3770.5014 | Q35: =Model2.0!BY48 -> 3845.9114 | V35: =Model2.0!BZ48 -> 3922.8297 | AA35: =Model2.0!CA48 -> 4001.2862
D36: Telephone & Internet | G36: =Model2.0!BW49 -> 10913.51 | L36: =Model2.0!BX49 -> 11131.78 | Q36: =Model2.0!BY49 -> 11354.416 | V36: =Model2.0!BZ49 -> 11581.504 | AA36: =Model2.0!CA49 -> 11813.134
D37: Software | G37: =Model2.0!BW50 -> 22200 | L37: =Model2.0!BX50 -> 22533 | Q37: =Model2.0!BY50 -> 22870.995 | V37: =Model2.0!BZ50 -> 23214.06 | AA37: =Model2.0!CA50 -> 23562.271 | AG37: x | AH37: increase
D38: Bank Charges | G38: =Model2.0!BW51 -> 0 | L38: =Model2.0!BX51 -> 0 | Q38: =Model2.0!BY51 -> 0 | V38: =Model2.0!BZ51 -> 0 | AA38: =Model2.0!CA51 -> 0
D39: Prof Fees - Legal/Acctg | G39: =Model2.0!BW52 -> 1940.76 | L39: =Model2.0!BX52 -> 1979.5752 | Q39: =Model2.0!BY52 -> 2019.1667 | V39: =Model2.0!BZ52 -> 2059.55 | AA39: =Model2.0!CA52 -> 2100.741
D40: Utilities | G40: =Model2.0!BW53 -> 28122.84 | L40: =Model2.0!BX53 -> 28685.297 | Q40: =Model2.0!BY53 -> 29259.003 | V40: =Model2.0!BZ53 -> 29844.183 | AA40: =Model2.0!CA53 -> 30441.066
D41: Insurance | G41: =Model2.0!BW54 -> 0 | L41: =Model2.0!BX54 -> 0 | Q41: =Model2.0!BY54 -> 0 | V41: =Model2.0!BZ54 -> 0 | AA41: =Model2.0!CA54 -> 0
D42: Property Taxes | G42: =Model2.0!BW55 -> 0 | L42: =Model2.0!BX55 -> 0 | M42: ="Assumed "&TEXT('Inputs & Drivers'!$J$62,"0%")&" Growth Rate" -> Assumed 1% Growth Rate | Q42: =Model2.0!BY55 -> 0 | R42: ="Assumed "&TEXT('Inputs & Drivers'!$J$63,"0%")&" Growth Rate" -> Assumed 1% Growth Rate | V42: =Model2.0!BZ55 -> 0 | W42: ="Assumed "&TEXT('Inputs & Drivers'!$J$64,"0%")&" Growth Rate" -> Assumed 1% Growth Rate | AA42: =Model2.0!CA55 -> 0 | AB42: ="Assumed "&TEXT('Inputs & Drivers'!$J$65,"0%")&" Growth Rate" -> Assumed 1% Growth Rate
D43: Other Expense | G43: =Model2.0!BW56 -> 0 | L43: =Model2.0!BX56 -> 0 | M43: ="Assumed "&TEXT('Inputs & Drivers'!$J$62,"0%")&" Growth Rate" -> Assumed 1% Growth Rate | Q43: =Model2.0!BY56 -> 0 | R43: ="Assumed "&TEXT('Inputs & Drivers'!$J$63,"0%")&" Growth Rate" -> Assumed 1% Growth Rate | V43: =Model2.0!BZ56 -> 0 | W43: ="Assumed "&TEXT('Inputs & Drivers'!$J$64,"0%")&" Growth Rate" -> Assumed 1% Growth Rate | AA43: =Model2.0!CA56 -> 0
D45: Total Operating Expense | G45: =SUM(G30:G43,G27:G28,G26,G24) -> 297496.11 | L45: =SUM(L30:L43,L27:L28,L26,L24) -> 310104.75 | Q45: =SUM(Q30:Q43,Q27:Q28,Q26,Q24) -> 323892.82 | V45: =SUM(V30:V43,V27:V28,V26,V24) -> 331610.29 | AA45: =SUM(AA30:AA43,AA27:AA28,AA26,AA24) -> 339535.55
D47: Net Operating Income | G47: =G21-G45 -> 1001731.7 | L47: =L21-L45 -> 1025246.5 | Q47: =Q21-Q45 -> 1059120.4 | V47: =V21-V45 -> 1102099.5 | AA47: =AA21-AA45 -> 1147789
L51: =L47-G47 -> 23514.814 | Q51: =Q47-L47 -> 33873.89 | V51: =V47-Q47 -> 42979.144 | AA51: =AA47-V47 -> 45689.508
...

Sheet Inputs & Drivers
B2: Inputs
B4: Property Overview
B5: Name | E5: Vacaville Property
B6: Type | E6: Storage
B7: Location | E7: 5920 Cherry Glen Rd, Vacaville, CA 95688
B8: Units Available | E8: 604
B9: Units Occupied | E9: 554
B10: NRSF | E10: 89350
B11: Acquisition Assumptions | G11: Sales Assumptions
B12: Acquisition Date | E12: 46082 | G12: Financing
B13: Hold Period | E13: 5 | G13: Loan-to-Value (LTV) | I13: 0.65
B14: Purchase Price | E14: 14000000 | G14: SOFR Rate | I14: 0.043 | J14: As of Mar 2026 (~4.30%)
B15: Acquisition Closing Costs | E15: 0.01 | G15: Spread (bps) | I15: 0.02 | J15: 240 bps
G16: All-In Rate | I16: =I14+I15 -> 0.063
G17: Amortization (Years) | I17: 25
G18: Loan Term (Years) | I18: 5
G19: Loan Amount | I19: =E14*I13 -> 9100000
G21: Capital Expenditures
G22: Upfront CapEx (Day 1) | I22: 25000
G23: Year 1 CapEx (Mo. 6-12) | I23: 0
G24: Total CapEx | I24: =I22+I23 -> 25000
G25: Annual CapEx Reserve (Yr 2-5) | I25: 0 | J25: Adjust if needed
G27: Exit Assumptions
G28: Exit Cap Rate | I28: 0.0625
G29: Disposition Costs | I29: 0.02
G30: Going-In Cap Rate | I30: =Model2.0!F60/E14 -> 0.045309753 | J30: T-12 NOI / Purchase Price
G31: Asset Management Fee | I31: 75000 | J31: Annual
B32: Drivers
B34: In-place Income (T-3) | G34: In-place Expenses
D35: Assumption | E35: Total | H35: % | I35: Per Rentable SqFt | J35: Total
B36: Occupancy | E36: =Model2.0!E24 -> 0.91721854 | G36: Advertising & Marketing | I36: 0.39012222 | J36: =I36*$E$10 -> 34857.42 | L36: 34857.42 | M36: =L36/$E$10 -> 0.39012222 | N36: Advertising & Marketing
B37: Effective Rate / SqFt | E37: =Model2.0!E23 -> 1.0390211 | G37: Current Credit Card Security Fees | H37: 0.014429716 | I37: 0 | J37: =H37*E42 -> 14744.524 | L37: 13333.74 | M37: 0 | N37: Current Credit Card Security Fees
G38: STORE Credit Card Security Fees | H38: 0 | I38: 0 | M38: =L38/$E$10 -> 0 | N38: STORE Credit Card Security Fees
B39: Rental Income | E39: =E37*(E10*E36)*12 -> 1021816.7 | G39: Fire Prevention | I39: 0.085007536 | J39: =I39*$E$10 -> 7595.4233 | L39: 0 | M39: =L39/$E$10 -> 0 | N39: Fire Prevention
B40: Discounts | D40: =-E40/$E$39 -> 0 | E40: =Model2.0!E21 -> 0 | G40: Licenses & Permits | I40: 0.0045914941 | J40: =I40*$E$10 -> 410.25 | L40: 410.25 | M40: =L40/$E$10 -> 0.0045914941 | N40: Licenses & Permits
B41: Bad Debt/Rental Refunds | D41: =-E41/$E$39 -> 0 | E41: 0 | G41: Current Mgmt. Fee | H41: 0.06 | I41: 0 | J41: =H41*E42 -> 61309.001 | L41: 46924.36 | M41: 0 | N41: Current Mgmt. Fee
B42: Total Rental Income | E42: =SUM(E39:E41) -> 1021816.7 | G42: STORE Mgmt. Fee | H42: 0.04 | I42: 0 | J42: =H42*E42 -> 40872.667 | L42: 0 | M42: =L42/$E$10 -> 0 | N42: STORE Mgmt. Fee
B43: Admin Fee Income | D43: 29 | E43: =Model2.0!E27 -> 29888.72 | G43: Payroll | I43: 1.00598 | J43: =(((52*($D$53*$D$55)+(D54*(($D$53*$D$55))))/12)+((D44*$E$9)*12))*12 -> 95022.864 | L43: 89884.31 | M43: =L43/$E$10 -> 1.00598 | N43: Payroll
B44: Late Fee Income | D44: ='P-Builder'!F82 -> 0.13431688 | E44: =Model2.0!E28 -> 29888.72 | G44: Office Supplies | I44: 0.018577728 | J44: =I44*$E$10 -> 1659.92 | L44: 1659.92 | M44: =L44/$E$10 -> 0.018577728 | N44: Office Supplies
B45: Current Tenant Protection Split | E45: =Model2.0!E29 -> 38040 | G45: Repairs & Maintenance | I45: 0.44530084 | J45: =I45*$E$10 -> 39787.63 | L45: 39787.63 | M45: =L45/$E$10 -> 0.44530084 | N45: Repairs & Maintenance
...

Sheet Model2.0
B2: Model | BV2: x
U3: x | AG3: x | AS3: x | BE3: x
B4: NRSF | C4: ='Inputs & Drivers'!E10 -> 89350 | E4: 0.25 | F4: =E4/12 -> 0.020833333 | H4: Monthly | BR4: Comparison
B5: Start Date | C5: ='Inputs & Drivers'!E12 -> 46082 | H5: 0 | I5: 1 | J5: 1 | K5: 1 | L5: 1 | M5: 1 | N5: 1 | O5: 1 | P5: 1 | Q5: 1 | R5: 1 | S5: 1 | T5: =1+H5 -> 1 | U5: =1+I5 -> 2 | V5: =1+J5 -> 2 | W5: =1+K5 -> 2 | X5: =1+L5 -> 2 | Y5: =1+M5 -> 2 | Z5: =1+N5 -> 2 | AA5: =1+O5 -> 2 | ... BP5: =1+BD5 -> 5 | BR5: 1
B6: Units Available | C6: ='Inputs & Drivers'!E8 -> 604 | H6: 0 | I6: =++H6+1 -> 1 | J6: =++I6+1 -> 2 | K6: =++J6+1 -> 3 | L6: =++K6+1 -> 4 | M6: =++L6+1 -> 5 | N6: =++M6+1 -> 6 | O6: =++N6+1 -> 7 | P6: =++O6+1 -> 8 | ... BP6: =++BO6+1 -> 60
B7: Units Occupied | C7: ='Inputs & Drivers'!E9 -> 554 | E7: T-3 | F7: T-12 | H7: =C5 -> 46082 | I7: =EOMONTH(H7,1) -> 46142 | J7: =EOMONTH(I7,1) -> 46173 | K7: =EOMONTH(J7,1) -> 46203 | L7: =EOMONTH(K7,1) -> 46234 | M7: =EOMONTH(L7,1) -> 46265 | N7: =EOMONTH(M7,1) -> 46295 | O7: =EOMONTH(N7,1) -> 46326 | P7: =EOMONTH(O7,1) -> 46356 | ... BP7: =EOMONTH(BO7,1) -> 47938 | BR7: STORE | BS7: Current Mgmt | BT7: Additional Revenue
B9: Net Rentable SqFt | E9: =C4 -> 89350 | F9: =C4 -> 89350 | I9: =$C$4 -> 89350 | J9: =$C$4 -> 89350 | K9: =$C$4 -> 89350 | L9: =$C$4 -> 89350 | M9: =$C$4 -> 89350 | N9: =$C$4 -> 89350 | O9: =$C$4 -> 89350 | P9: =$C$4 -> 89350 | ... BP9: =$C$4 -> 89350
B10: Projected Rate ($/sqft) | E10: =E19/($C$4*E24)/12 -> 1.0390211 | F10: =H19/($C$4*F24) -> 1.0793785 | H10: =H19/($C$4*E24) -> 1.0793785 | I10: =(1+(INDEX('Inputs & Drivers'!$E$61:$E$65,MATCH(Model2.0!I$5,'Inputs & Drivers'!$B$61:$B$65,0))/12))*H10 -> 1.0865743 | J10: =(1+(INDEX('Inputs & Drivers'!$E$61:$E$65,MATCH(Model2.0!J$5,'Inputs & Drivers'!$B$61:$B$65,0))/12))*I10 -> 1.0938182 | K10: =(1+(INDEX('Inputs & Drivers'!$E$61:$E$65,MATCH(Model2.0!K$5,'Inputs & Drivers'!$B$61:$B$65,0))/12))*J10 -> 1.1011103 | L10: =(1+(INDEX('Inputs & Drivers'!$E$61:$E$65,MATCH(Model2.0!L$5,'Inputs & Drivers'!$B$61:$B$65,0))/12))*K10 -> 1.108451 | M10: =(1+(INDEX('Inputs & Drivers'!$E$61:$E$65,MATCH(Model2.0!M$5,'Inputs & Drivers'!$B$61:$B$65,0))/12))*L10 -> 1.1158407 | N10: =(1+(INDEX('Inputs & Drivers'!$E$61:$E$65,MATCH(Model2.0!N$5,'Inputs & Drivers'!$B$61:$B$65,0))/12))*M10 -> 1.1232796 | O10: =(1+(INDEX('Inputs & Drivers'!$E$61:$E$65,MATCH(Model2.0!O$5,'Inputs & Drivers'!$B$61:$B$65,0))/12))*N10 -> 1.1307682 | P10: =(1+(INDEX('Inputs & Drivers'!$E$61:$E$65,MATCH(Model2.0!P$5,'Inputs & Drivers'!$B$61:$B$65,0))/12))*O10 -> 1.1383066 | ... BP10: =(1+(INDEX('Inputs & Drivers'!$E$61:$E$65,MATCH(Model2.0!BP$5,'Inputs & Drivers'!$B$61:$B$65,0))/12))*BO10 -> 1.3714298
B11: General Vacancy | E11: =1-E24 -> 0.082781457 | F11: =1-F24 -> 0.082781457 | I11: =($C$6-I15)/$C$6 -> 0.082781457 | J11: =($C$6-J15)/$C$6 -> 0.082781457 | K11: =($C$6-K15)/$C$6 -> 0.082781457 | L11: =($C$6-L15)/$C$6 -> 0.082781457 | M11: =($C$6-M15)/$C$6 -> 0.082781457 | N11: =($C$6-N15)/$C$6 -> 0.082781457 | O11: =($C$6-O15)/$C$6 -> 0.082781457 | P11: =($C$6-P15)/$C$6 -> 0.082781457 | ... BP11: =($C$6-BP15)/$C$6 -> 0.082781457
B12: ECRI | F12: ECRI | I12: 0 | J12: 0 | K12: 0 | L12: 0.05 | M12: 0.05 | N12: 0.05 | O12: 0.02 | P12: 0.02 | Q12: 0.02 | R12: 0.02 | S12: 0.02 | T12: 0.02 | U12: 0.05 | V12: 0.01 | W12: 0.01 | X12: 0.01 | Y12: 0.01 | Z12: 0.01 | AA12: 0.01 | AB12: 0.01 | AC12: 0.01 | AD12: 0.01 | AE12: 0.01 | AF12: 0.01 | AG12: 0.05 | AH12: 0.01 | AI12: 0.01 | AJ12: 0.01 | AK12: 0.01 | AL12: 0.01 | AM12: 0.01 | AN12: 0.01 | AO12: 0.01 | AP12: 0.01 | AQ12: 0.01 | AR12: 0.01 | AS12: 0.05 | AT12: 0.01 | AU12: 0.01 | AV12: 0.01 | AW12: 0.01 | AX12: 0.01 | AY12: 0.01 | AZ12: 0.01 | BA12: 0.01 | BB12: 0.01 | BC12: 0.01 | BD12: 0.01 | BE12: 0.05 | BF12: 0.01 | BG12: 0.01 | BH12: 0.01 | BI12: 0.01 | BJ12: 0.01 | BK12: 0.01 | BL12: 0.01 | BM12: 0.01 | BN12: 0.01 | BO12: 0.01 | BP12: 0.01
B13: Move-ins | H13: 20 | I13: 20 | J13: 20 | K13: 20 | L13: 20 | M13: 20 | N13: 20 | O13: 20 | P13: 20 | Q13: 20 | R13: 20 | S13: 20 | T13: 20 | U13: 20 | V13: 20 | W13: 20 | X13: 20 | Y13: 20 | Z13: 20 | AA13: 20 | AB13: 20 | AC13: 20 | AD13: 20 | AE13: 20 | AF13: 20 | AG13: 20 | AH13: 20 | AI13: 20 | AJ13: 20 | AK13: 20 | AL13: 20 | AM13: 20 | AN13: 20 | AO13: 20 | AP13: 20 | AQ13: 20 | AR13: 20 | AS13: 20 | AT13: 20 | AU13: 20 | AV13: 20 | AW13: 20 | AX13: 20 | AY13: 20 | AZ13: 20 | BA13: 20 | BB13: 20 | BC13: 20 | BD13: 20 | BE13: 20 | BF13: 20 | BG13: 20 | BH13: 20 | BI13: 20 | BJ13: 20 | BK13: 20 | BL13: 20 | BM13: 20 | BN13: 20 | BO13: 20 | BP13: 20
B14: Move-Outs | H14: 20 | I14: 20 | J14: 20 | K14: 20 | L14: 20 | M14: 20 | N14: 20 | O14: 20 | P14: 20 | Q14: 20 | R14: 20 | S14: 20 | T14: 20 | U14: 20 | V14: 20 | W14: 20 | X14: 20 | Y14: 20 | Z14: 20 | AA14: 20 | AB14: 20 | AC14: 20 | AD14: 20 | AE14: 20 | AF14: 20 | AG14: 20 | AH14: 20 | AI14: 20 | AJ14: 20 | AK14: 20 | AL14: 20 | AM14: 20 | AN14: 20 | AO14: 20 | AP14: 20 | AQ14: 20 | AR14: 20 | AS14: 20 | AT14: 20 | AU14: 20 | AV14: 20 | AW14: 20 | AX14: 20 | AY14: 20 | AZ14: 20 | BA14: 20 | BB14: 20 | BC14: 20 | BD14: 20 | BE14: 20 | BF14: 20 | BG14: 20 | BH14: 20 | BI14: 20 | BJ14: 20 | BK14: 20 | BL14: 20 | BM14: 20 | BN14: 20 | BO14: 20 | BP14: 20
B15: Occupied Units | E15: =C7 -> 554 | F15: =C7 -> 554 | H15: =E15+(H13-H14) -> 554 | I15: =F15+(I13-I14) -> 554 | J15: =I15+(J13-J14) -> 554 | K15: =J15+(K13-K14) -> 554 | L15: =K15+(L13-L14) -> 554 | M15: =L15+(M13-M14) -> 554 | N15: =M15+(N13-N14) -> 554 | O15: =N15+(O13-O14) -> 554 | P15: =O15+(P13-P14) -> 554 | Q15: =P15+(Q13-Q14) -> 554 | ... BP15: =BO15+(BP13-BP14) -> 554
B16: Tenant Protection Capture | H16: 0.6 | I16: =H16+0.02 -> 0.62 | J16: =I16+0.02 -> 0.64 | K16: =J16+0.02 -> 0.66 | L16: =K16+0.02 -> 0.68 | M16: =L16+0.02 -> 0.7 | N16: =M16+0.02 -> 0.72 | O16: =N16+0.02 -> 0.74 | P16: =O16+0.02 -> 0.76 | ... R16: =Q16+0.02 -> 0.8 | S16: =R16 -> 0.8 | T16: =S16 -> 0.8 | U16: =T16 -> 0.8 | V16: =U16 -> 0.8 | W16: =V16 -> 0.8 | X16: =W16 -> 0.8 | Y16: =X16 -> 0.8 | Z16: =Y16 -> 0.8 | ... BP16: =BO16 -> 0.8 | BW16: Yearly
E17: =1-E11 -> 0.91721854 | F17: =1-F11 -> 0.91721854 | I17: =1-I11 -> 0.91721854 | J17: =1-J11 -> 0.91721854 | K17: =1-K11 -> 0.91721854 | L17: =1-L11 -> 0.91721854 | M17: =1-M11 -> 0.91721854 | N17: =1-N11 -> 0.91721854 | O17: =1-O11 -> 0.91721854 | P17: =1-P11 -> 0.91721854 | ... BP17: =1-BP11 -> 0.91721854
B18: Income | BV18: Income | BW18: 1 | BX18: 2 | BY18: 3 | BZ18: 4 | CA18: 5
B19: Rental Income | E19: =SUM('P-Builder'!O5:Q5)*4 -> 1021816.7 | F19: =SUM('P-Builder'!F5:Q5) -> 832809.83 | H19: ='P-Builder'!Q5 -> 88458.82 | I19: =I10*(I9*(1-I11)) -> 89048.545 | J19: =J10*(J9*(1-J11)) -> 89642.202 | K19: =K10*(K9*(1-K11)) -> 90239.817 | L19: =L10*(L9*(1-L11)) -> 90841.416 | M19: =M10*(M9*(1-M11)) -> 91447.025 | N19: =N10*(N9*(1-N11)) -> 92056.672 | O19: =O10*(O9*(1-O11)) -> 92670.383 | P19: =P10*(P9*(1-P11)) -> 93288.186 | ... BP19: =BP10*(BP9*(1-BP11)) -> 112393.44 | BR19: =SUM(I19:T19) -> 1108647.8 | BS19: =(E19*1.07)+ABS(BR21) -> 1133367.2 | BT19: =BR19-BS19 -> -24719.431 | BV19: Rental Income | BW19: =SUMIF($I$5:$BP$5,BW$18,$I19:$BP19) -> 1108647.8 | BX19: =SUMIF($I$5:$BP$5,BX$18,$I19:$BP19) -> 1174825.5 | BY19: =SUMIF($I$5:$BP$5,BY$18,$I19:$BP19) -> 1222689.7 | BZ19: =SUMIF($I$5:$BP$5,BZ$18,$I19:$BP19) -> 1272504 | CA19: =SUMIF($I$5:$BP$5,CA$18,$I19:$BP19) -> 1324347.8 | CC19: =SUM($I19:$T19) -> 1108647.8 | CD19: =SUM($U19:$AF19) -> 1174825.5 | CE19: =SUM($AG19:$AR19) -> 1222689.7 | CF19: =SUM($AS19:$BD19) -> 1272504 | CG19: =SUM($BE19:$BP19) -> 1324347.8 | CI19: =IF(CC19=BW19,"OK","Check") -> OK | CJ19: =IF(CD19=BX19,"OK","Check") -> OK | CK19: =IF(CE19=BY19,"OK","Check") -> OK | CL19: =IF(CF19=BZ19,"OK","Check") -> OK | CM19: =IF(CG19=CA19,"OK","Check") -> OK
B20: STORE Rate Mgmt. Rev | E20: 0 | F20: 0 | H20: =H19*H12 -> 0 | I20: =IF(I5=H5,H20+(I19*I12),I19*I12) -> 0 | J20: =IF(J5=I5,I20+(J19*J12),J19*J12) -> 0 | K20: =IF(K5=J5,J20+(K19*K12),K19*K12) -> 0 | L20: =IF(L5=K5,K20+(L19*L12),L19*L12) -> 4542.0708 | M20: =IF(M5=L5,L20+(M19*M12),M19*M12) -> 9114.4221 | N20: =IF(N5=M5,M20+(N19*N12),N19*N12) -> 13717.256 | O20: =IF(O5=N5,N20+(O19*O12),O19*O12) -> 15570.663 | P20: =IF(P5=O5,O20+(P19*P12),P19*P12) -> 17436.427 | ... BP20: =IF(BP5=BO5,BO20+(BP19*BP12),BP19*BP12) -> 17577.621 | BR20: =SUM(I20:T20) -> 149034.2 | BS20: =E20 -> 0 | BT20: =BR20-BS20 -> 149034.2 | BV20: STORE Rate Mgmt. Rev | BW20: =SUMIF($I$5:$BP$5,BW$18,$I20:$BP20) -> 149034.2 | BX20: =SUMIF($I$5:$BP$5,BX$18,$I20:$BP20) -> 122035.47 | BY20: =SUMIF($I$5:$BP$5,BY$18,$I20:$BP20) -> 127007.39 | BZ20: =SUMIF($I$5:$BP$5,BZ$18,$I20:$BP20) -> 132181.86 | CA20: =SUMIF($I$5:$BP$5,CA$18,$I20:$BP20) -> 137567.16 | CC20: =SUM($I20:$T20) -> 149034.2 | CD20: =SUM($U20:$AF20) -> 122035.47 | CE20: =SUM($AG20:$AR20) -> 127007.39 | CF20: =SUM($AS20:$BD20) -> 132181.86 | CG20: =SUM($BE20:$BP20) -> 137567.16 | CI20: =IF(CC20=BW20,"OK","Check") -> OK | CJ20: =IF(CD20=BX20,"OK","Check") -> OK | CK20: =IF(CE20=BY20,"OK","Check") -> OK | CL20: =IF(CF20=BZ20,"OK","Check") -> OK | CM20: =IF(CG20=CA20,"OK","Check") -> OK
B21: Discounts | E21: =SUM('P-Builder'!O6:Q6)*4 -> 0 | F21: =SUM('P-Builder'!F6:Q6) -> 0 | H21: ='P-Builder'!Q7 -> 0 | I21: =((I10*I13)*($C$4/$C$6))*(-1) -> -3214.7489 | J21: =((J10*J13)*($C$4/$C$6))*(-1) -> -3236.1806 | K21: =((K10*K13)*($C$4/$C$6))*(-1) -> -3257.7551 | L21: =((L10*L13)*($C$4/$C$6))*(-1) -> -3279.4735 | M21: =((M10*M13)*($C$4/$C$6))*(-1) -> -3301.3367 | N21: =((N10*N13)*($C$4/$C$6))*(-1) -> -3323.3456 | O21: =((O10*O13)*($C$4/$C$6))*(-1) -> -3345.5012 | P21: =((P10*P13)*($C$4/$C$6))*(-1) -> -3367.8045 | ... BP21: =((BP10*BP13)*($C$4/$C$6))*(-1) -> -4057.5249 | BR21: =SUM(I21:T21) -> -40023.386 | BS21: =BR21 -> -40023.386 | BT21: =BR21-BS21 -> 0 | BV21: Discounts | BW21: =SUMIF($I$5:$BP$5,BW$18,$I21:$BP21) -> -40023.386 | BX21: =SUMIF($I$5:$BP$5,BX$18,$I21:$BP21) -> -42412.473 | BY21: =SUMIF($I$5:$BP$5,BY$18,$I21:$BP21) -> -44140.423 | BZ21: =SUMIF($I$5:$BP$5,BZ$18,$I21:$BP21) -> -45938.772 | CA21: =SUMIF($I$5:$BP$5,CA$18,$I21:$BP21) -> -47810.388 | CC21: =SUM($I21:$T21) -> -40023.386 | CD21: =SUM($U21:$AF21) -> -42412.473 | CE21: =SUM($AG21:$AR21) -> -44140.423 | CF21: =SUM($AS21:$BD21) -> -45938.772 | CG21: =SUM($BE21:$BP21) -> -47810.388 | CI21: =IF(CC21=BW21,"OK","Check") -> OK | CJ21: =IF(CD21=BX21,"OK","Check") -> OK | CK21: =IF(CE21=BY21,"OK","Check") -> OK | CL21: =IF(CF21=BZ21,"OK","Check") -> OK | CM21: =IF(CG21=CA21,"OK","Check") -> OK
B22: Net Rental Income | E22: =SUM(E19:E21) -> 1021816.7 | F22: =SUM(F19:F21) -> 832809.83 | H22: ='P-Builder'!Q8 -> 88458.82 | I22: =SUM(I19:I21) -> 85833.797 | J22: =SUM(J19:J21) -> 86406.022 | K22: =SUM(K19:K21) -> 86982.062 | L22: =SUM(L19:L21) -> 92104.013 | M22: =SUM(M19:M21) -> 97260.111 | N22: =SUM(N19:N21) -> 102450.58 | O22: =SUM(O19:O21) -> 104895.55 | P22: =SUM(P19:P21) -> 107356.81 | ... BP22: =SUM(BP19:BP21) -> 125913.54 | BR22: =SUM(BR19:BR21) -> 1217658.6 | BS22: =SUM(BS19:BS21) -> 1093343.8 | BT22: =BR22-BS22 -> 124314.77 | BV22: Net Rental Income | BW22: =SUMIF($I$5:$BP$5,BW$18,$I22:$BP22) -> 1217658.6 | BX22: =SUMIF($I$5:$BP$5,BX$18,$I22:$BP22) -> 1254448.5 | BY22: =SUMIF($I$5:$BP$5,BY$18,$I22:$BP22) -> 1305556.7 | BZ22: =SUMIF($I$5:$BP$5,BZ$18,$I22:$BP22) -> 1358747.1 | CA22: =SUMIF($I$5:$BP$5,CA$18,$I22:$BP22) -> 1414104.5 | CC22: =SUM($I22:$T22) -> 1217658.6 | CD22: =SUM($U22:$AF22) -> 1254448.5 | CE22: =SUM($AG22:$AR22) -> 1305556.7 | CF22: =SUM($AS22:$BD22) -> 1358747.1 | CG22: =SUM($BE22:$BP22) -> 1414104.5
B23: Effective Rent / Month | E23: =E19/($C$4*E24)/12 -> 1.0390211 | F23: =F19/($C$4*F24)/12 -> 0.84683191 | H23: ='Inputs & Drivers'!E37 -> 1.0390211 | I23: =I19/($C$4*I24) -> 1.0865743 | J23: =J19/($C$4*J24) -> 1.0938182 | K23: =K19/($C$4*K24) -> 1.1011103 | L23: =L19/($C$4*L24) -> 1.108451 | M23: =M19/($C$4*M24) -> 1.1158407 | N23: =N19/($C$4*N24) -> 1.1232796 | O23: =O19/($C$4*O24) -> 1.1307682 | P23: =P19/($C$4*P24) -> 1.1383066 | ... BP23: =BP19/($C$4*BP24) -> 1.3714298 | CC23: =IF(CC22=BW22,"OK","Check") -> OK | CD23: =IF(CD22=BX22,"OK","Check") -> OK | CE23: =IF(CE22=BY22,"OK","Check") -> OK | CF23: =IF(CF22=BZ22,"OK","Check") -> OK | CG23: =IF(CG22=CA22,"OK","Check") -> OK
B24: Physical Occupancy | E24: =C7/C6 -> 0.91721854 | F24: =C7/C6 -> 0.91721854 | H24: =H15/$C$6 -> 0.91721854 | I24: =I15/$C$6 -> 0.91721854 | J24: =J15/$C$6 -> 0.91721854 | K24: =K15/$C$6 -> 0.91721854 | L24: =L15/$C$6 -> 0.91721854 | M24: =M15/$C$6 -> 0.91721854 | N24: =N15/$C$6 -> 0.91721854 | O24: =O15/$C$6 -> 0.91721854 | ... BP24: =BP15/$C$6 -> 0.91721854
B27: Admin Fee Income | E27: =SUM('P-Builder'!O10:Q10)*4 -> 29888.72 | F27: =SUM('P-Builder'!F10:Q10) -> 22165.125 | H27: ='Inputs & Drivers'!D43*H13 -> 580 | I27: =I13*'Inputs & Drivers'!$D$43 -> 580 | J27: =J13*'Inputs & Drivers'!$D$43 -> 580 | K27: =K13*'Inputs & Drivers'!$D$43 -> 580 | L27: =L13*'Inputs & Drivers'!$D$43 -> 580 | M27: =M13*'Inputs & Drivers'!$D$43 -> 580 | N27: =N13*'Inputs & Drivers'!$D$43 -> 580 | O27: =O13*'Inputs & Drivers'!$D$43 -> 580 | P27: =P13*'Inputs & Drivers'!$D$43 -> 580 | ... BP27: =BP13*'Inputs & Drivers'!$D$43 -> 580 | BR27: =SUM(I27:T27) -> 6960 | BS27: =SUM(I27:T27) -> 6960 | BT27: =BR27-BS27 -> 0 | BV27: Admin Fee Income | BW27: =SUMIF($I$5:$BP$5,BW$18,$I27:$BP27) -> 6960 | BX27: =SUMIF($I$5:$BP$5,BX$18,$I27:$BP27) -> 6960 | BY27: =SUMIF($I$5:$BP$5,BY$18,$I27:$BP27) -> 6960 | BZ27: =SUMIF($I$5:$BP$5,BZ$18,$I27:$BP27) -> 6960 | CA27: =SUMIF($I$5:$BP$5,CA$18,$I27:$BP27) -> 6960 | CC27: =SUM($I27:$T27) -> 6960 | CD27: =SUM($U27:$AF27) -> 6960 | CE27: =SUM($AG27:$AR27) -> 6960 | CF27: =SUM($AS27:$BD27) -> 6960 | CG27: =SUM($BE27:$BP27) -> 6960 | CI27: =IF(CC27=BW27,"OK","Check") -> OK | CJ27: =IF(CD27=BX27,"OK","Check") -> OK | CK27: =IF(CE27=BY27,"OK","Check") -> OK | CL27: =IF(CF27=BZ27,"OK","Check") -> OK | CM27: =IF(CG27=CA27,"OK","Check") -> OK
B28: Late Fee Income | E28: =SUM('P-Builder'!O11:Q11)*4 -> 29888.72 | F28: =SUM('P-Builder'!F11:Q11) -> 22165.125 | H28: =(H19*'Inputs & Drivers'!D44)*0.2 -> 2376.3026 | I28: =(I19*'Inputs & Drivers'!D44)*0.2 -> 2392.1446 | J28: =I28*0.98 -> 2344.3017 | K28: =J28*0.98 -> 2297.4157 | L28: =K28*0.98 -> 2251.4674 | M28: =L28*0.98 -> 2206.438 | N28: =M28*0.98 -> 2162.3092 | O28: =N28*0.98 -> 2119.0631 | P28: =O28*0.98 -> 2076.6818 | Q28: =P28*0.98 -> 2035.1482 | ... BP28: =BO28*0.98 -> 726.31647 | BR28: =SUM(I28:T28) -> 25749.436 | BS28: =SUM(I28:T28) -> 25749.436 | BT28: =BR28-BS28 -> 0 | BV28: Late Fee Income | BW28: =SUMIF($I$5:$BP$5,BW$18,$I28:$BP28) -> 25749.436 | BX28: =SUMIF($I$5:$BP$5,BX$18,$I28:$BP28) -> 20206.013 | BY28: =SUMIF($I$5:$BP$5,BY$18,$I28:$BP28) -> 15855.997 | BZ28: =SUMIF($I$5:$BP$5,BZ$18,$I28:$BP28) -> 12442.466 | CA28: =SUMIF($I$5:$BP$5,CA$18,$I28:$BP28) -> 9763.8109 | CC28: =SUM($I28:$T28) -> 25749.436 | CD28: =SUM($U28:$AF28) -> 20206.013 | CE28: =SUM($AG28:$AR28) -> 15855.997 | CF28: =SUM($AS28:$BD28) -> 12442.466 | CG28: =SUM($BE28:$BP28) -> 9763.8109 | CI28: =IF(CC28=BW28,"OK","Check") -> OK | CJ28: =IF(CD28=BX28,"OK","Check") -> OK | CK28: =IF(CE28=BY28,"OK","Check") -> OK | CL28: =IF(CF28=BZ28,"OK","Check") -> OK | CM28: =IF(CG28=CA28,"OK","Check") -> OK
B29: Current Tenant Protection Split | E29: =SUM('P-Builder'!O12:Q12)*4 -> 38040 | F29: =SUM('P-Builder'!F12:Q12) -> 35796 | H29: =F29/12 -> 2983 | I29: =H29*1.002 -> 2988.966 | J29: =I29*1.002 -> 2994.9439 | K29: =J29*1.002 -> 3000.9338 | L29: =K29*1.002 -> 3006.9357 | M29: =L29*1.002 -> 3012.9496 | N29: =M29*1.002 -> 3018.9755 | O29: =N29*1.002 -> 3025.0134 | P29: =O29*1.002 -> 3031.0634 | ... BP29: =BO29*1.002 -> 3362.9201 | BR29: 0 | BS29: =SUM(I29:T29) -> 36264.778 | BV29: Current Tenant Protection Split | BW29: =SUMIF($I$5:$BP$5,BW$18,$I29:$BP29) -> 36264.778 | BX29: =SUMIF($I$5:$BP$5,BX$18,$I29:$BP29) -> 37144.77 | BY29: =SUMIF($I$5:$BP$5,BY$18,$I29:$BP29) -> 38046.117 | BZ29: =SUMIF($I$5:$BP$5,BZ$18,$I29:$BP29) -> 38969.335 | CA29: =SUMIF($I$5:$BP$5,CA$18,$I29:$BP29) -> 39914.956 | CC29: =SUM($I29:$T29) -> 36264.778 | CD29: =SUM($U29:$AF29) -> 37144.77 | CE29: =SUM($AG29:$AR29) -> 38046.117 | CF29: =SUM($AS29:$BD29) -> 38969.335 | CG29: =SUM($BE29:$BP29) -> 39914.956 | CI29: =IF(CC29=BW29,"OK","Check") -> OK | CJ29: =IF(CD29=BX29,"OK","Check") -> OK | CK29: =IF(CE29=BY29,"OK","Check") -> OK | CL29: =IF(CF29=BZ29,"OK","Check") -> OK | CM29: =IF(CG29=CA29,"OK","Check") -> OK
B30: STORE Tenant Protection Split | E30: =SUM('P-Builder'!O13:Q13)*4 -> 0 | F30: =SUM('P-Builder'!F13:Q13) -> 0 | H30: 15 | I30: =((I15*'Inputs & Drivers'!$D$70)*I16)*'Inputs & Drivers'!$D$71*(1+'Inputs & Drivers'!$L$70)^(I5-1) -> 2747.84 | J30: =((J15*'Inputs & Drivers'!$D$70)*J16)*'Inputs & Drivers'!$D$71*(1+'Inputs & Drivers'!$L$70)^(J5-1) -> 2836.48 | K30: =((K15*'Inputs & Drivers'!$D$70)*K16)*'Inputs & Drivers'!$D$71*(1+'Inputs & Drivers'!$L$70)^(K5-1) -> 2925.12 | L30: =((L15*'Inputs & Drivers'!$D$70)*L16)*'Inputs & Drivers'!$D$71*(1+'Inputs & Drivers'!$L$70)^(L5-1) -> 3013.76 | M30: =((M15*'Inputs & Drivers'!$D$70)*M16)*'Inputs & Drivers'!$D$71*(1+'Inputs & Drivers'!$L$70)^(M5-1) -> 3102.4 | N30: =((N15*'Inputs & Drivers'!$D$70)*N16)*'Inputs & Drivers'!$D$71*(1+'Inputs & Drivers'!$L$70)^(N5-1) -> 3191.04 | O30: =((O15*'Inputs & Drivers'!$D$70)*O16)*'Inputs & Drivers'!$D$71*(1+'Inputs & Drivers'!$L$70)^(O5-1) -> 3279.68 | P30: =((P15*'Inputs & Drivers'!$D$70)*P16)*'Inputs & Drivers'!$D$71*(1+'Inputs & Drivers'!$L$70)^(P5-1) -> 3368.32 | ... BP30: =((BP15*'Inputs & Drivers'!$D$70)*BP16)*'Inputs & Drivers'!$D$71*(1+'Inputs & Drivers'!$L$70)^(BP5-1) -> 3763.1706 | BR30: =SUM(I30:T30) -> 38558.4 | BS30: 0 | BT30: =BR30-BS29 -> 2293.6223 | BV30: STORE Tenant Protection Split | BW30: =SUMIF($I$5:$BP$5,BW$18,$I30:$BP30) -> 38558.4 | BX30: =SUMIF($I$5:$BP$5,BX$18,$I30:$BP30) -> 43185.408 | BY30: =SUMIF($I$5:$BP$5,BY$18,$I30:$BP30) -> 43833.189 | BZ30: =SUMIF($I$5:$BP$5,BZ$18,$I30:$BP30) -> 44490.687 | CA30: =SUMIF($I$5:$BP$5,CA$18,$I30:$BP30) -> 45158.047 | CC30: =SUM($I30:$T30) -> 38558.4 | CD30: =SUM($U30:$AF30) -> 43185.408 | CE30: =SUM($AG30:$AR30) -> 43833.189 | CF30: =SUM($AS30:$BD30) -> 44490.687 | CG30: =SUM($BE30:$BP30) -> 45158.047 | CI30: =IF(CC30=BW30,"OK","Check") -> OK | CJ30: =IF(CD30=BX30,"OK","Check") -> OK | CK30: =IF(CE30=BY30,"OK","Check") -> OK | CL30: =IF(CF30=BZ30,"OK","Check") -> OK | CM30: =IF(CG30=CA30,"OK","Check") -> OK
B31: Other Tenant Income | E31: =SUM('P-Builder'!O14:Q14)*4 -> 0 | F31: =SUM('P-Builder'!F14:Q14) -> 0 | H31: =E31/12 -> 0 | I31: =H31*1.002 -> 0 | J31: =I31*1.002 -> 0 | K31: =J31*1.002 -> 0 | L31: =K31*1.002 -> 0 | M31: =L31*1.002 -> 0 | N31: =M31*1.002 -> 0 | O31: =N31*1.002 -> 0 | P31: =O31*1.002 -> 0 | ... BP31: =BO31*1.002 -> 0 | BR31: =SUM(I31:T31) -> 0 | BS31: =SUM(I31:T31) -> 0 | BT31: =BR31-BS31 -> 0 | BV31: Other Tenant Income | BW31: =SUMIF($I$5:$BP$5,BW$18,$I31:$BP31) -> 0 | BX31: =SUMIF($I$5:$BP$5,BX$18,$I31:$BP31) -> 0 | BY31: =SUMIF($I$5:$BP$5,BY$18,$I31:$BP31) -> 0 | BZ31: =SUMIF($I$5:$BP$5,BZ$18,$I31:$BP31) -> 0 | CA31: =SUMIF($I$5:$BP$5,CA$18,$I31:$BP31) -> 0 | CC31: =SUM($I31:$T31) -> 0 | CD31: =SUM($U31:$AF31) -> 0 | CE31: =SUM($AG31:$AR31) -> 0 | CF31: =SUM($AS31:$BD31) -> 0 | CG31: =SUM($BE31:$BP31) -> 0 | CI31: =IF(CC31=BW31,"OK","Check") -> OK | CJ31: =IF(CD31=BX31,"OK","Check") -> OK | CK31: =IF(CE31=BY31,"OK","Check") -> OK | CL31: =IF(CF31=BZ31,"OK","Check") -> OK | CM31: =IF(CG31=CA31,"OK","Check") -> OK
B32: Retail Sales Income | E32: =SUM('P-Builder'!O15:Q15)*4 -> 10168.16 | F32: =SUM('P-Builder'!F15:Q15) -> 10231.93 | H32: =E32/12 -> 847.34667 | I32: =H32*1.002 -> 849.04136 | J32: =I32*1.002 -> 850.73944 | K32: =J32*1.002 -> 852.44092 | L32: =K32*1.002 -> 854.1458 | M32: =L32*1.002 -> 855.8541 | N32: =M32*1.002 -> 857.5658 | O32: =N32*1.002 -> 859.28093 | P32: =O32*1.002 -> 860.9995 | ... BP32: =BO32*1.002 -> 955.26621 | BR32: =SUM(I32:T32) -> 10301.32 | BS32: =SUM(I32:T32) -> 10301.32 | BT32: =BR32-BS32 -> 0 | BV32: Retail Sales Income | BW32: =SUMIF($I$5:$BP$5,BW$18,$I32:$BP32) -> 10301.32 | BX32: =SUMIF($I$5:$BP$5,BX$18,$I32:$BP32) -> 10551.29 | BY32: =SUMIF($I$5:$BP$5,BY$18,$I32:$BP32) -> 10807.325 | BZ32: =SUMIF($I$5:$BP$5,BZ$18,$I32:$BP32) -> 11069.573 | CA32: =SUMIF($I$5:$BP$5,CA$18,$I32:$BP32) -> 11338.185 | CC32: =SUM($I32:$T32) -> 10301.32 | CD32: =SUM($U32:$AF32) -> 10551.29 | CE32: =SUM($AG32:$AR32) -> 10807.325 | CF32: =SUM($AS32:$BD32) -> 11069.573 | CG32: =SUM($BE32:$BP32) -> 11338.185 | CI32: =IF(CC32=BW32,"OK","Check") -> OK | CJ32: =IF(CD32=BX32,"OK","Check") -> OK | CK32: =IF(CE32=BY32,"OK","Check") -> OK | CL32: =IF(CF32=BZ32,"OK","Check") -> OK | CM32: =IF(CG32=CA32,"OK","Check") -> OK
B34: Total Operating Income | E34: =SUM(E27:E32,E22) -> 1129802.3 | F34: =SUM(F22,F27:F32) -> 923168.01 | I34: =SUM(I22,I27:I28,I30:I32) -> 92402.822 | J34: =SUM(J22,J27:J28,J30:J32) -> 93017.543 | K34: =SUM(K22,K27:K28,K30:K32) -> 93637.039 | L34: =SUM(L22,L27:L28,L30:L32) -> 98803.386 | M34: =SUM(M22,M27:M28,M30:M32) -> 104004.8 | N34: =SUM(N22,N27:N28,N30:N32) -> 109241.5 | O34: =SUM(O22,O27:O28,O30:O32) -> 111733.57 | P34: =SUM(P22,P27:P28,P30:P32) -> 114242.81 | ... BP34: =SUM(BP22,BP27:BP28,BP30:BP32) -> 131938.29 | BR34: =SUM(BR22,BR27:BR32) -> 1299227.8 | BS34: =SUM(BS22,BS27:BS32) -> 1172619.4 | BT34: =BR34-BS34 -> 126608.39 | BV34: Total Operating Income | BW34: =SUM(BW30:BW32,BW27:BW28,BW22) -> 1299227.8 | BX34: =SUM(BX30:BX32,BX27:BX28,BX22) -> 1335351.2 | BY34: =SUM(BY30:BY32,BY27:BY28,BY22) -> 1383013.2 | BZ34: =SUM(BZ30:BZ32,BZ27:BZ28,BZ22) -> 1433709.8 | CA34: =SUM(CA30:CA32,CA27:CA28,CA22) -> 1487324.6 | CC34: =SUM($I34:$T34) -> 1299227.8 | CD34: =SUM($U34:$AF34) -> 1335351.2 | CE34: =SUM($AG34:$AR34) -> 1383013.2 | CF34: =SUM($AS34:$BD34) -> 1433709.8 | CG34: =SUM($BE34:$BP34) -> 1487324.6 | CI34: =IF(CC34=BW34,"OK","Check") -> OK | CJ34: =IF(CD34=BX34,"OK","Check") -> OK | CK34: =IF(CE34=BY34,"OK","Check") -> OK | CL34: =IF(CF34=BZ34,"OK","Check") -> OK | CM34: =IF(CG34=CA34,"OK","Check") -> OK
BX35: =(BX34-BW34)/BW34 -> 0.027803784 | BY35: =(BY34-BX34)/BX34 -> 0.035692458 | BZ35: =(BZ34-BY34)/BY34 -> 0.036656634 | CA35: =(CA34-BZ34)/BZ34 -> 0.037395831 | CC35: =IF(CC34=BW34,"OK","Check") -> OK | CD35: =IF(CD34=BX34,"OK","Check") -> OK | CE35: =IF(CE34=BY34,"OK","Check") -> OK | CF35: =IF(CF34=BZ34,"OK","Check") -> OK | CG35: =IF(CG34=CA34,"OK","Check") -> OK
B36: Expenses | H36: LAST MONTH | BV36: Expenses
B37: Advertising & Marketing | E37: =SUM('P-Builder'!O20:Q20)*4 -> 23123.88 | F37: =SUM('P-Builder'!F20:Q20) -> 34857.42 | H37: ='P-Builder'!Q20 -> 2235.45 | I37: 3000 | J37: =(1+INDEX('Inputs & Drivers'!$I$61:$I$65,MATCH(Model2.0!J$5,'Inputs & Drivers'!$B$61:$B$65,0))*(Model2.0!J$5<>Model2.0!I$5))*Model2.0!I37 -> 3000 | K37: =(1+INDEX('Inputs & Drivers'!$I$61:$I$65,MATCH(Model2.0!K$5,'Inputs & Drivers'!$B$61:$B$65,0))*(Model2.0!K$5<>Model2.0!J$5))*Model2.0!J37 -> 3000 | L37: =(1+INDEX('Inputs & Drivers'!$I$61:$I$65,MATCH(Model2.0!L$5,'Inputs & Drivers'!$B$61:$B$65,0))*(Model2.0!L$5<>Model2.0!K$5))*Model2.0!K37 -> 3000 | M37: =(1+INDEX('Inputs & Drivers'!$I$61:$I$65,MATCH(Model2.0!M$5,'Inputs & Drivers'!$B$61:$B$65,0))*(Model2.0!M$5<>Model2.0!L$5))*Model2.0!L37 -> 3000 | N37: =(1+INDEX('Inputs & Drivers'!$I$61:$I$65,MATCH(Model2.0!N$5,'Inputs & Drivers'!$B$61:$B$65,0))*(Model2.0!N$5<>Model2.0!M$5))*Model2.0!M37 -> 3000 | O37: =(1+INDEX('Inputs & Drivers'!$I$61:$I$65,MATCH(Model2.0!O$5,'Inputs & Drivers'!$B$61:$B$65,0))*(Model2.0!O$5<>Model2.0!N$5))*Model2.0!N37 -> 3000 | P37: =(1+INDEX('Inputs & Drivers'!$I$61:$I$65,MATCH(Model2.0!P$5,'Inputs & Drivers'!$B$61:$B$65,0))*(Model2.0!P$5<>Model2.0!O$5))*Model2.0!O37 -> 3000 | Q37: =(1+INDEX('Inputs & Drivers'!$I$61:$I$65,MATCH(Model2.0!Q$5,'Inputs & Drivers'!$B$61:$B$65,0))*(Model2.0!Q$5<>Model2.0!P$5))*Model2.0!P37 -> 3000 | ... BP37: =(1+INDEX('Inputs & Drivers'!$I$61:$I$65,MATCH(Model2.0!BP$5,'Inputs & Drivers'!$B$61:$B$65,0))*(Model2.0!BP$5<>Model2.0!BO$5))*Model2.0!BO37 -> 3247.2965 | BR37: =SUM(I37:T37) -> 36000 | BS37: =SUM(I37:T37) -> 36000 | BT37: =BS37-BR37 -> 0 | BV37: Advertising & Marketing | BW37: =SUMIF($I$5:$BP$5,BW$18,$I37:$BP37) -> 36000 | BX37: =SUMIF($I$5:$BP$5,BX$18,$I37:$BP37) -> 36720 | BY37: =SUMIF($I$5:$BP$5,BY$18,$I37:$BP37) -> 37454.4 | BZ37: =SUMIF($I$5:$BP$5,BZ$18,$I37:$BP37) -> 38203.488 | CA37: =SUMIF($I$5:$BP$5,CA$18,$I37:$BP37) -> 38967.558 | CC37: =SUM($I37:$T37) -> 36000 | CD37: =SUM($U37:$AF37) -> 36720 | CE37: =SUM($AG37:$AR37) -> 37454.4 | CF37: =SUM($AS37:$BD37) -> 38203.488 | CG37: =SUM($BE37:$BP37) -> 38967.558 | CI37: =IF(CC37=BW37,"OK","Check") -> OK | CJ37: =IF(CD37=BX37,"OK","Check") -> OK | CK37: =IF(CE37=BY37,"OK","Check") -> OK | CL37: =IF(CF37=BZ37,"OK","Check") -> OK | CM37: =IF(CG37=CA37,"OK","Check") -> OK
B38: Current Credit Card Security Fees | E38: =SUM('P-Builder'!O21:Q21)*4 -> 16760.4 | F38: =SUM('P-Builder'!F21:Q21) -> 13333.74 | H38: ='P-Builder'!Q21 -> 1484.59 | I38: =I34*'Inputs & Drivers'!$H$37 -> 1333.3464 | J38: =J34*'Inputs & Drivers'!$H$37 -> 1342.2167 | K38: =K34*'Inputs & Drivers'!$H$37 -> 1351.1558 | L38: =L34*'Inputs & Drivers'!$H$37 -> 1425.7048 | M38: =M34*'Inputs & Drivers'!$H$37 -> 1500.7597 | N38: =N34*'Inputs & Drivers'!$H$37 -> 1576.3237 | O38: =O34*'Inputs & Drivers'!$H$37 -> 1612.2836 | P38: =P34*'Inputs & Drivers'!$H$37 -> 1648.4912 | ... BP38: =BP34*'Inputs & Drivers'!$H$37 -> 1903.832 | BR38: 0 | BS38: =SUM(I38:T38) -> 18747.487 | BV38: Current Credit Card Security Fees | BW38: =SUMIF($I$5:$BP$5,BW$18,$I38:$BP38) -> 18747.487 | BX38: =SUMIF($I$5:$BP$5,BX$18,$I38:$BP38) -> 19268.738 | BY38: =SUMIF($I$5:$BP$5,BY$18,$I38:$BP38) -> 19956.487 | BZ38: =SUMIF($I$5:$BP$5,BZ$18,$I38:$BP38) -> 20688.024 | CA38: =SUMIF($I$5:$BP$5,CA$18,$I38:$BP38) -> 21461.67 | CC38: =SUM($I38:$T38) -> 18747.487 | CD38: =SUM($U38:$AF38) -> 19268.738 | CE38: =SUM($AG38:$AR38) -> 19956.487 | CF38: =SUM($AS38:$BD38) -> 20688.024 | CG38: =SUM($BE38:$BP38) -> 21461.67 | CI38: =IF(CC38=BW38,"OK","Check") -> OK | CJ38: =IF(CD38=BX38,"OK","Check") -> OK | CK38: =IF(CE38=BY38,"OK","Check") -> OK | CL38: =IF(CF38=BZ38,"OK","Check") -> OK | CM38: =IF(CG38=CA38,"OK","Check") -> OK
